import mujoco
import mujoco_viewer
import numpy as np
import random

#Defining graph class and functions
class Graph:
    def __init__(self):
        self.graph = {}
        self.length = 0

    def add_vertex(self, vertex):
        if vertex not in self.graph:
            self.graph[vertex] = []
            self.length += 1

    def add_edge(self, from_vertex, to_vertex):
        if from_vertex in self.graph and to_vertex in self.graph:
            self.graph[from_vertex].append(to_vertex)

    def display(self):
        for vertex in self.graph:
            print(f"{vertex}: {self.graph[vertex]}")

    def get_length(self):
        return self.length
        
    def get_edges (self, vertex):
        return self.graph[vertex]

#Defining creature class and functions
class Creature:
    def __init__(self, uid, xml, graph, posns):
        self.id = uid
        self.xml = xml
        self.graph = graph
        self.posns = posns

    def get_id(self):
        return self.id

    def get_xml (self):
        return self.xml
    
    def get_posns (self):
        return self.posns
    
    def get_graph(self):
        return self.graph
    
    def display(self):
        print( self.id, self.xml, self.graph)

#Defining population class and functions
class Population:
    def __init__(self):
        self.population = set()
        
    def add_creature(self, creature):
        if creature not in self.population:
            self.population.add(creature)
    
    def get_creature(self, uid):
        for creature in self.population:
            if creature.get_id() == uid:
                return creature
    

#Mutable XML template
xml = """
<mujoco>
    <option gravity = '0 0 -9.81'/>
    <worldbody>
        <light diffuse = '.5 .5 .5' pos = '0 0 6' dir = '0 0 -1'/>
        <geom type = 'plane' size = '5 5 0.1' rgba = '1 1 1 1'/>
        <body name = '0' pos = '0 0 1'>
            <joint type = 'free'/>
            {}
        </body>
    </worldbody>
    {}
</mujoco>
"""

#XML Components
generic_geom = """<geom type='{}' size='{}' mass='{}'/>"""
generic_joint = """<joint type='{}' name='{}' axis='{}' range='{}'/>"""
motor = "<motor name ='{}' joint='{}'/>"

box = """<geom type="box" size=".1 .2 .1" rgba="1 0 0 1"/>"""
sphere = """<geom type="sphere" size=".3" rgba="0 1 0 1" mass='0.1'/>"""
joint = """<joint type='{}' name='{}'  axis = '-1 0 0' range = '0 35'/>"""

body = """
        <body name = '{}' pos='{}' euler='{}'> 
            {}
        </body>"""
actuatorXML = """
    <actuator>
        {}
    </actuator>"""
    

# Initial generation developed through randomized graphs
# 

# Generate randomized posns for initial generations of models
def generate_posn ():
    x = random.randrange(0,2, 0.1)
    y = random.randrange(0,2, 0.1)
    z = random.randrange(0,2, 0.1)
    return (x,y,z)

# Generate xml string based on graph
def generate_xml(id, population):
    parentCreature = population.get_creature(id)
    parentGraph = parentCreature.get_graph()
    parentPosns = parentCreature.get_posns()
    print(parentPosns)
    parentLength = parentGraph.get_length()
    #XML string for limbs
    limbsXML = ""
    #XML string for joint motors
    motorXML = ""
    limbs = 1
    segs = 1
    posnIndex = 0
    for i in range(parentLength):
        edges = parentGraph.get_edges(i)
        if len(edges) > 0:
            limbs += len([x for x in edges if x != i])
            if i != 0:
                segs += len([j for j in edges if j != i])
    for i in range(limbs):
        entityGraph.add_vertex(i+1)
        entityGraph.add_edge(0,i+1)      
        segXML = ''
        #Create hierarchy of limb segments
        for j in range(segs):
            entityGraph.add_edge(i+1, i+1)
            if j == 0:
                segXML = body
            if j != segs-1:
                segXML = segXML.format(f"limb{i}-seg-{j}", "0 .2 -.1", f"{(-90/segs)} 0 0", box+body)
            else:
                segXML = segXML.format(f"limb{i}-seg-{j}", "0 .2 -.1", f"{(-90/segs)} 0 0", box)
        limbsXML += body.format(f"limb-{i+1}", f"{parentPosns[posnIndex][0]} {parentPosns[posnIndex][1]} {parentPosns[posnIndex][2]}",
                            f"{parentPosns[posnIndex][3]} {parentPosns[posnIndex][4]} {parentPosns[posnIndex][5]}", 
                            joint.format('hinge', i+1)+box+segXML)
        motorXML += motor.format(f"motor-limb-{i+1}", i+1)
        posnIndex += 1

    #Format xml string
    jumpingXML = xml.format(sphere+limbsXML, actuatorXML.format(motorXML))
    population.add_creature(Creature(creature_uid, jumpingXML, entityGraph, posn))
    return jumpingXML

#Possible limb positions and rotations - currently hardcoded
posn = [(0.5,0,0,0,0,-90), (-0.5,0,0,0,0,90), (0,0.5,0,0,0,0), (0,-0.5,0,0,0,180)]

#Select a random number of models that compete
models = random.randrange(2,4)

population = Population()
modelArray = []
maxIndex = -1
maxRatio = -1
creature_uid = 0

# Convert this as a way to build models from graph rather than simultaneous
for z in range(1):
    #Initialize graph and add 0 index value corresponding to body
    entityGraph = Graph()
    entityGraph.add_vertex(0)
    #Select a random number of limbs to generate on body
    limbs = random.randrange(2,5)
    
    #Select random number of segments per limb
    segs = random.randrange(1,5)  

    #XML string for limbs
    limbsXML = ""

    #XML string for joint motors
    motorXML = ""
    #Track index in posn array
    posnIndex = 0

    #Add edges from body to limbs and build limbs XML
    for i in range(limbs):
        entityGraph.add_vertex(i+1)
        entityGraph.add_edge(0,i+1)      
        segXML = ''
        #Create hierarchy of limb segments
        for j in range(segs):
            entityGraph.add_edge(i+1, i+1)
            if j == 0:
                segXML = body
            if j != segs-1:
                segXML = segXML.format(f"limb{i}-seg-{j}", "0 .2 -.1", f"{(-90/segs)} 0 0", box+body)
            else:
                segXML = segXML.format(f"limb{i}-seg-{j}", "0 .2 -.1", f"{(-90/segs)} 0 0", box)
        limbsXML += body.format(f"limb-{i+1}", f"{posn[posnIndex][0]} {posn[posnIndex][1]} {posn[posnIndex][2]}",
                            f"{posn[posnIndex][3]} {posn[posnIndex][4]} {posn[posnIndex][5]}", 
                            joint.format('hinge', i+1)+box+segXML)
        motorXML += motor.format(f"motor-limb-{i+1}", i+1)
        posnIndex += 1

    #Format xml string
    jumpingXML = xml.format(sphere+limbsXML, actuatorXML.format(motorXML))
    population.add_creature(Creature(creature_uid, jumpingXML, entityGraph, posn))
    child = generate_xml(creature_uid, population)
    creature_uid += 1

    #Display corresponding genotype graph
    #Note: Edge to self represents 1 additional segmentation
    entityGraph.display()
    

    #Make model and data
    model = mujoco.MjModel.from_xml_string(child)
    data = mujoco.MjData(model)

    #Make viewer
    viewer = mujoco_viewer.MujocoViewer(model, data)

    #Get array of actuators
    actuators = model.nu

    #Create list of velocities for corresponding limb motors
    velocities = np.array([500*segs for i in range(limbs)])
    jump = False
    maxHeight = 0
    heightOffset = 0
    for i in range(10000):
        if viewer.is_alive:
            if np.all(np.abs(data.qvel) < 0.01) and i%50:
                # Consider the starting position of the model, takes into account length of limbs
                if heightOffset == 0:
                    heightOffset = data.qpos[2]
                data.ctrl[:actuators] = velocities
                jump = True
                velocities*=-1
            else:
                if jump == True:
                    # tracks the max height of the model
                    if data.qpos[2] < maxHeight:
                        break
                    else:
                        maxHeight = max(maxHeight, data.qpos[2])
            mujoco.mj_step(model, data)
            viewer.render()
        else:
            break
    # Fitness is the proportion of maximum height in relation to starting position
    if float(maxHeight/heightOffset) > maxRatio:
        maxRatio = float(maxHeight/heightOffset)
        maxIndex = z
    viewer.close()
    print(maxHeight, heightOffset)
    print(maxRatio)
population.get_creature(maxIndex).display()